Workbook
Name Slicer_Representative: #N/A

Sheet Data
A1: Call Number | B1: Customer ID | C1: Duration (Min) | D1: Representative | E1: Date of Call | F1: Purchase Amount | G1: Satisfactory Rating | H1: Rounded Rating | I1: Duration Bucket | J1: FY | K1: Day of week | L1: Month | P1: Customer ID | Q1: Gender | R1: Age | S1: City
A2: call_1000 | B2: C018 | C2: 32 | D2: R006 | E2: 1-Jan-25 | F2: 101 | G2: 3.7 | H2: =ROUND(Calls[[#This Row],[Satisfactory Rating]],0) -> 4 | I2: {=_xlfn.IFS(Calls[[#This Row],[Duration (Min)]]<=30,"Under 30 mins",Calls[[#This Row],[Duration (Min)]]<=60,"Under 1h",Calls[[#This Row],[Duration (Min)]]<=120,"Under 2",TRUE,"More than 2h")} -> Under 1h | J2: =IF(MONTH(Calls[[#This Row],[Date of Call]])<=3,YEAR(Calls[[#This Row],[Date of Call]]),YEAR(Calls[[#This Row],[Date of Call]])+1) -> 2025 | K2: =TEXT(Calls[[#This Row],[Date of Call]],"dddd") -> Wednesday | L2: =TEXT(Calls[[#This Row],[Date of Call]],"mmm") -> Jan | P2: C001 | Q2: Female | R2: 31 | S2: Chennai
A3: call_1001 | B3: C012 | C3: 53 | D3: R001 | E3: 1-Jan-25 | F3: 122 | G3: 2 | H3: =ROUND(Calls[[#This Row],[Satisfactory Rating]],0) -> 2 | I3: {=_xlfn.IFS(Calls[[#This Row],[Duration (Min)]]<=30,"Under 30 mins",Calls[[#This Row],[Duration (Min)]]<=60,"Under 1h",Calls[[#This Row],[Duration (Min)]]<=120,"Under 2",TRUE,"More than 2h")} -> Under 1h | J3: =IF(MONTH(Calls[[#This Row],[Date of Call]])<=3,YEAR(Calls[[#This Row],[Date of Call]]),YEAR(Calls[[#This Row],[Date of Call]])+1) -> 2025 | K3: =TEXT(Calls[[#This Row],[Date of Call]],"dddd") -> Wednesday | L3: =TEXT(Calls[[#This Row],[Date of Call]],"mmm") -> Jan | P3: C002 | Q3: Female | R3: 55 | S3: Chennai
A4: call_1002 | B4: C018 | C4: 59 | D4: R004 | E4: 1-Jan-25 | F4: 124 | G4: 2.4 | H4: =ROUND(Calls[[#This Row],[Satisfactory Rating]],0) -> 2 | I4: {=_xlfn.IFS(Calls[[#This Row],[Duration (Min)]]<=30,"Under 30 mins",Calls[[#This Row],[Duration (Min)]]<=60,"Under 1h",Calls[[#This Row],[Duration (Min)]]<=120,"Under 2",TRUE,"More than 2h")} -> Under 1h | J4: =IF(MONTH(Calls[[#This Row],[Date of Call]])<=3,YEAR(Calls[[#This Row],[Date of Call]]),YEAR(Calls[[#This Row],[Date of Call]])+1) -> 2025 | K4: =TEXT(Calls[[#This Row],[Date of Call]],"dddd") -> Wednesday | L4: =TEXT(Calls[[#This Row],[Date of Call]],"mmm") -> Jan | P4: C003 | Q4: Female | R4: 33 | S4: Madurai
A5: call_1003 | B5: C003 | C5: 11 | D5: R005 | E5: 1-Jan-25 | F5: 150 | G5: 3.1 | H5: =ROUND(Calls[[#This Row],[Satisfactory Rating]],0) -> 3 | I5: {=_xlfn.IFS(Calls[[#This Row],[Duration (Min)]]<=30,"Under 30 mins",Calls[[#This Row],[Duration (Min)]]<=60,"Under 1h",Calls[[#This Row],[Duration (Min)]]<=120,"Under 2",TRUE,"More than 2h")} -> Under 30 mins | J5: =IF(MONTH(Calls[[#This Row],[Date of Call]])<=3,YEAR(Calls[[#This Row],[Date of Call]]),YEAR(Calls[[#This Row],[Date of Call]])+1) -> 2025 | K5: =TEXT(Calls[[#This Row],[Date of Call]],"dddd") -> Wednesday | L5: =TEXT(Calls[[#This Row],[Date of Call]],"mmm") -> Jan | P5: C004 | Q5: Male | R5: 42 | S5: Trichy
A6: call_1004 | B6: C005 | C6: 83 | D6: R006 | E6: 1-Jan-25 | F6: 49 | G6: 3.2 | H6: =ROUND(Calls[[#This Row],[Satisfactory Rating]],0) -> 3 | I6: {=_xlfn.IFS(Calls[[#This Row],[Duration (Min)]]<=30,"Under 30 mins",Calls[[#This Row],[Duration (Min)]]<=60,"Under 1h",Calls[[#This Row],[Duration (Min)]]<=120,"Under 2",TRUE,"More than 2h")} -> Under 2 | J6: =IF(MONTH(Calls[[#This Row],[Date of Call]])<=3,YEAR(Calls[[#This Row],[Date of Call]]),YEAR(Calls[[#This Row],[Date of Call]])+1) -> 2025 | K6: =TEXT(Calls[[#This Row],[Date of Call]],"dddd") -> Wednesday | L6: =TEXT(Calls[[#This Row],[Date of Call]],"mmm") -> Jan | P6: C005 | Q6: Male | R6: 19 | S6: Salem
A7: call_1005 | B7: C019 | C7: 22 | D7: R004 | E7: 2-Jan-25 | F7: 27 | G7: 1.7 | H7: =ROUND(Calls[[#This Row],[Satisfactory Rating]],0) -> 2 | I7: {=_xlfn.IFS(Calls[[#This Row],[Duration (Min)]]<=30,"Under 30 mins",Calls[[#This Row],[Duration (Min)]]<=60,"Under 1h",Calls[[#This Row],[Duration (Min)]]<=120,"Under 2",TRUE,"More than 2h")} -> Under 30 mins | J7: =IF(MONTH(Calls[[#This Row],[Date of Call]])<=3,YEAR(Calls[[#This Row],[Date of Call]]),YEAR(Calls[[#This Row],[Date of Call]])+1) -> 2025 | K7: =TEXT(Calls[[#This Row],[Date of Call]],"dddd") -> Thursday | L7: =TEXT(Calls[[#This Row],[Date of Call]],"mmm") -> Jan | P7: C006 | Q7: Female | R7: 20 | S7: Trichy
A8: call_1006 | B8: C019 | C8: 63 | D8: R003 | E8: 2-Jan-25 | F8: 66 | G8: 4.5 | H8: =ROUND(Calls[[#This Row],[Satisfactory Rating]],0) -> 5 | I8: {=_xlfn.IFS(Calls[[#This Row],[Duration (Min)]]<=30,"Under 30 mins",Calls[[#This Row],[Duration (Min)]]<=60,"Under 1h",Calls[[#This Row],[Duration (Min)]]<=120,"Under 2",TRUE,"More than 2h")} -> Under 2 | J8: =IF(MONTH(Calls[[#This Row],[Date of Call]])<=3,YEAR(Calls[[#This Row],[Date of Call]]),YEAR(Calls[[#This Row],[Date of Call]])+1) -> 2025 | K8: =TEXT(Calls[[#This Row],[Date of Call]],"dddd") -> Thursday | L8: =TEXT(Calls[[#This Row],[Date of Call]],"mmm") -> Jan | P8: C007 | Q8: Female | R8: 34 | S8: Trichy
A9: call_1007 | B9: C018 | C9: 90 | D9: R004 | E9: 2-Jan-25 | F9: 106 | G9: 2.7 | H9: =ROUND(Calls[[#This Row],[Satisfactory Rating]],0) -> 3 | I9: {=_xlfn.IFS(Calls[[#This Row],[Duration (Min)]]<=30,"Under 30 mins",Calls[[#This Row],[Duration (Min)]]<=60,"Under 1h",Calls[[#This Row],[Duration (Min)]]<=120,"Under 2",TRUE,"More than 2h")} -> Under 2 | J9: =IF(MONTH(Calls[[#This Row],[Date of Call]])<=3,YEAR(Calls[[#This Row],[Date of Call]]),YEAR(Calls[[#This Row],[Date of Call]])+1) -> 2025 | K9: =TEXT(Calls[[#This Row],[Date of Call]],"dddd") -> Thursday | L9: =TEXT(Calls[[#This Row],[Date of Call]],"mmm") -> Jan | P9: C008 | Q9: Male | R9: 26 | S9: Chennai
A10: call_1008 | B10: C017 | C10: 108 | D10: R006 | E10: 2-Jan-25 | F10: 97 | G10: 3 | H10: =ROUND(Calls[[#This Row],[Satisfactory Rating]],0) -> 3 | I10: {=_xlfn.IFS(Calls[[#This Row],[Duration (Min)]]<=30,"Under 30 mins",Calls[[#This Row],[Duration (Min)]]<=60,"Under 1h",Calls[[#This Row],[Duration (Min)]]<=120,"Under 2",TRUE,"More than 2h")} -> Under 2 | J10: =IF(MONTH(Calls[[#This Row],[Date of Call]])<=3,YEAR(Calls[[#This Row],[Date of Call]]),YEAR(Calls[[#This Row],[Date of Call]])+1) -> 2025 | K10: =TEXT(Calls[[#This Row],[Date of Call]],"dddd") -> Thursday | L10: =TEXT(Calls[[#This Row],[Date of Call]],"mmm") -> Jan | P10: C009 | Q10: Male | R10: 27 | S10: Salem
A11: call_1009 | B11: C014 | C11: 143 | D11: R002 | E11: 2-Jan-25 | F11: 113 | G11: 4 | H11: =ROUND(Calls[[#This Row],[Satisfactory Rating]],0) -> 4 | I11: {=_xlfn.IFS(Calls[[#This Row],[Duration (Min)]]<=30,"Under 30 mins",Calls[[#This Row],[Duration (Min)]]<=60,"Under 1h",Calls[[#This Row],[Duration (Min)]]<=120,"Under 2",TRUE,"More than 2h")} -> More than 2h | J11: =IF(MONTH(Calls[[#This Row],[Date of Call]])<=3,YEAR(Calls[[#This Row],[Date of Call]]),YEAR(Calls[[#This Row],[Date of Call]])+1) -> 2025 | K11: =TEXT(Calls[[#This Row],[Date of Call]],"dddd") -> Thursday | L11: =TEXT(Calls[[#This Row],[Date of Call]],"mmm") -> Jan | P11: C010 | Q11: Male | R11: 36 | S11: Salem
A12: call_1010 | B12: C008 | C12: 44 | D12: R002 | E12: 3-Jan-25 | F12: 118 | G12: 1.7 | H12: =ROUND(Calls[[#This Row],[Satisfactory Rating]],0) -> 2 | I12: {=_xlfn.IFS(Calls[[#This Row],[Duration (Min)]]<=30,"Under 30 mins",Calls[[#This Row],[Duration (Min)]]<=60,"Under 1h",Calls[[#This Row],[Duration (Min)]]<=120,"Under 2",TRUE,"More than 2h")} -> Under 1h | J12: =IF(MONTH(Calls[[#This Row],[Date of Call]])<=3,YEAR(Calls[[#This Row],[Date of Call]]),YEAR(Calls[[#This Row],[Date of Call]])+1) -> 2025 | K12: =TEXT(Calls[[#This Row],[Date of Call]],"dddd") -> Friday | L12: =TEXT(Calls[[#This Row],[Date of Call]],"mmm") -> Jan | P12: C011 | Q12: Female | R12: 37 | S12: Madurai
A13: call_1011 | B13: C013 | C13: 58 | D13: R003 | E13: 3-Jan-25 | F13: 70 | G13: 3.6 | H13: =ROUND(Calls[[#This Row],[Satisfactory Rating]],0) -> 4 | I13: {=_xlfn.IFS(Calls[[#This Row],[Duration (Min)]]<=30,"Under 30 mins",Calls[[#This Row],[Duration (Min)]]<=60,"Under 1h",Calls[[#This Row],[Duration (Min)]]<=120,"Under 2",TRUE,"More than 2h")} -> Under 1h | J13: =IF(MONTH(Calls[[#This Row],[Date of Call]])<=3,YEAR(Calls[[#This Row],[Date of Call]]),YEAR(Calls[[#This Row],[Date of Call]])+1) -> 2025 | K13: =TEXT(Calls[[#This Row],[Date of Call]],"dddd") -> Friday | L13: =TEXT(Calls[[#This Row],[Date of Call]],"mmm") -> Jan | P13: C012 | Q13: Male | R13: 41 | S13: Salem
... A21: call_1019 | B21: C018 | C21: 144 | D21: R005 | E21: 4-Jan-25 | F21: 33 | G21: 3.7 | H21: =ROUND(Calls[[#This Row],[Satisfactory Rating]],0) -> 4 | I21: {=_xlfn.IFS(Calls[[#This Row],[Duration (Min)]]<=30,"Under 30 mins",Calls[[#This Row],[Duration (Min)]]<=60,"Under 1h",Calls[[#This Row],[Duration (Min)]]<=120,"Under 2",TRUE,"More than 2h")} -> More than 2h | J21: =IF(MONTH(Calls[[#This Row],[Date of Call]])<=3,YEAR(Calls[[#This Row],[Date of Call]]),YEAR(Calls[[#This Row],[Date of Call]])+1) -> 2025 | K21: =TEXT(Calls[[#This Row],[Date of Call]],"dddd") -> Saturday | L21: =TEXT(Calls[[#This Row],[Date of Call]],"mmm") -> Jan | P21: C020 | Q21: Female | R21: 18 | S21: Chennai
A22: call_1020 | B22: C006 | C22: 142 | D22: R001 | E22: 5-Jan-25 | F22: 27 | G22: 4.4 | H22: =ROUND(Calls[[#This Row],[Satisfactory Rating]],0) -> 4 | I22: {=_xlfn.IFS(Calls[[#This Row],[Duration (Min)]]<=30,"Under 30 mins",Calls[[#This Row],[Duration (Min)]]<=60,"Under 1h",Calls[[#This Row],[Duration (Min)]]<=120,"Under 2",TRUE,"More than 2h")} -> More than 2h | J22: =IF(MONTH(Calls[[#This Row],[Date of Call]])<=3,YEAR(Calls[[#This Row],[Date of Call]]),YEAR(Calls[[#This Row],[Date of Call]])+1) -> 2025 | K22: =TEXT(Calls[[#This Row],[Date of Call]],"dddd") -> Sunday | L22: =TEXT(Calls[[#This Row],[Date of Call]],"mmm") -> Jan
A23: call_1021 | B23: C020 | C23: 20 | D23: R002 | E23: 5-Jan-25 | F23: 54 | G23: 3.2 | H23: =ROUND(Calls[[#This Row],[Satisfactory Rating]],0) -> 3 | I23: {=_xlfn.IFS(Calls[[#This Row],[Duration (Min)]]<=30,"Under 30 mins",Calls[[#This Row],[Duration (Min)]]<=60,"Under 1h",Calls[[#This Row],[Duration (Min)]]<=120,"Under 2",TRUE,"More than 2h")} -> Under 30 mins | J23: =IF(MONTH(Calls[[#This Row],[Date of Call]])<=3,YEAR(Calls[[#This Row],[Date of Call]]),YEAR(Calls[[#This Row],[Date of Call]])+1) -> 2025 | K23: =TEXT(Calls[[#This Row],[Date of Call]],"dddd") -> Sunday | L23: =TEXT(Calls[[#This Row],[Date of Call]],"mmm") -> Jan
A24: call_1022 | B24: C013 | C24: 110 | D24: R007 | E24: 5-Jan-25 | F24: 120 | G24: 4.7 | H24: =ROUND(Calls[[#This Row],[Satisfactory Rating]],0) -> 5 | I24: {=_xlfn.IFS(Calls[[#This Row],[Duration (Min)]]<=30,"Under 30 mins",Calls[[#This Row],[Duration (Min)]]<=60,"Under 1h",Calls[[#This Row],[Duration (Min)]]<=120,"Under 2",TRUE,"More than 2h")} -> Under 2 | J24: =IF(MONTH(Calls[[#This Row],[Date of Call]])<=3,YEAR(Calls[[#This Row],[Date of Call]]),YEAR(Calls[[#This Row],[Date of Call]])+1) -> 2025 | K24: =TEXT(Calls[[#This Row],[Date of Call]],"dddd") -> Sunday | L24: =TEXT(Calls[[#This Row],[Date of Call]],"mmm") -> Jan
A25: call_1023 | B25: C018 | C25: 27 | D25: R004 | E25: 5-Jan-25 | F25: 114 | G25: 3.2 | H25: =ROUND(Calls[[#This Row],[Satisfactory Rating]],0) -> 3 | I25: {=_xlfn.IFS(Calls[[#This Row],[Duration (Min)]]<=30,"Under 30 mins",Calls[[#This Row],[Duration (Min)]]<=60,"Under 1h",Calls[[#This Row],[Duration (Min)]]<=120,"Under 2",TRUE,"More than 2h")} -> Under 30 mins | J25: =IF(MONTH(Calls[[#This Row],[Date of Call]])<=3,YEAR(Calls[[#This Row],[Date of Call]]),YEAR(Calls[[#This Row],[Date of Call]])+1) -> 2025 | K25: =TEXT(Calls[[#This Row],[Date of Call]],"dddd") -> Sunday | L25: =TEXT(Calls[[#This Row],[Date of Call]],"mmm") -> Jan
A26: call_1024 | B26: C001 | C26: 16 | D26: R002 | E26: 5-Jan-25 | F26: 149 | G26: 1.9 | H26: =ROUND(Calls[[#This Row],[Satisfactory Rating]],0) -> 2 | I26: {=_xlfn.IFS(Calls[[#This Row],[Duration (Min)]]<=30,"Under 30 mins",Calls[[#This Row],[Duration (Min)]]<=60,"Under 1h",Calls[[#This Row],[Duration (Min)]]<=120,"Under 2",TRUE,"More than 2h")} -> Under 30 mins | J26: =IF(MONTH(Calls[[#This Row],[Date of Call]])<=3,YEAR(Calls[[#This Row],[Date of Call]]),YEAR(Calls[[#This Row],[Date of Call]])+1) -> 2025 | K26: =TEXT(Calls[[#This Row],[Date of Call]],"dddd") -> Sunday | L26: =TEXT(Calls[[#This Row],[Date of Call]],"mmm") -> Jan
A27: call_1025 | B27: C003 | C27: 120 | D27: R006 | E27: 6-Jan-25 | F27: 25 | G27: 2.4 | H27: =ROUND(Calls[[#This Row],[Satisfactory Rating]],0) -> 2 | I27: {=_xlfn.IFS(Calls[[#This Row],[Duration (Min)]]<=30,"Under 30 mins",Calls[[#This Row],[Duration (Min)]]<=60,"Under 1h",Calls[[#This Row],[Duration (Min)]]<=120,"Under 2",TRUE,"More than 2h")} -> Under 2 | J27: =IF(MONTH(Calls[[#This Row],[Date of Call]])<=3,YEAR(Calls[[#This Row],[Date of Call]]),YEAR(Calls[[#This Row],[Date of Call]])+1) -> 2025 | K27: =TEXT(Calls[[#This Row],[Date of Call]],"dddd") -> Monday | L27: =TEXT(Calls[[#This Row],[Date of Call]],"mmm") -> Jan
A28: call_1026 | B28: C013 | C28: 19 | D28: R002 | E28: 6-Jan-25 | F28: 59 | G28: 1.6 | H28: =ROUND(Calls[[#This Row],[Satisfactory Rating]],0) -> 2 | I28: {=_xlfn.IFS(Calls[[#This Row],[Duration (Min)]]<=30,"Under 30 mins",Calls[[#This Row],[Duration (Min)]]<=60,"Under 1h",Calls[[#This Row],[Duration (Min)]]<=120,"Under 2",TRUE,"More than 2h")} -> Under 30 mins | J28: =IF(MONTH(Calls[[#This Row],[Date of Call]])<=3,YEAR(Calls[[#This Row],[Date of Call]]),YEAR(Calls[[#This Row],[Date of Call]])+1) -> 2025 | K28: =TEXT(Calls[[#This Row],[Date of Call]],"dddd") -> Monday | L28: =TEXT(Calls[[#This Row],[Date of Call]],"mmm") -> Jan
A29: call_1027 | B29: C006 | C29: 11 | D29: R001 | E29: 6-Jan-25 | F29: 90 | G29: 3.6 | H29: =ROUND(Calls[[#This Row],[Satisfactory Rating]],0) -> 4 | I29: {=_xlfn.IFS(Calls[[#This Row],[Duration (Min)]]<=30,"Under 30 mins",Calls[[#This Row],[Duration (Min)]]<=60,"Under 1h",Calls[[#This Row],[Duration (Min)]]<=120,"Under 2",TRUE,"More than 2h")} -> Under 30 mins | J29: =IF(MONTH(Calls[[#This Row],[Date of Call]])<=3,YEAR(Calls[[#This Row],[Date of Call]]),YEAR(Calls[[#This Row],[Date of Call]])+1) -> 2025 | K29: =TEXT(Calls[[#This Row],[Date of Call]],"dddd") -> Monday | L29: =TEXT(Calls[[#This Row],[Date of Call]],"mmm") -> Jan
A30: call_1028 | B30: C014 | C30: 85 | D30: R005 | E30: 6-Jan-25 | F30: 77 | G30: 3.7 | H30: =ROUND(Calls[[#This Row],[Satisfactory Rating]],0) -> 4 | I30: {=_xlfn.IFS(Calls[[#This Row],[Duration (Min)]]<=30,"Under 30 mins",Calls[[#This Row],[Duration (Min)]]<=60,"Under 1h",Calls[[#This Row],[Duration (Min)]]<=120,"Under 2",TRUE,"More than 2h")} -> Under 2 | J30: =IF(MONTH(Calls[[#This Row],[Date of Call]])<=3,YEAR(Calls[[#This Row],[Date of Call]]),YEAR(Calls[[#This Row],[Date of Call]])+1) -> 2025 | K30: =TEXT(Calls[[#This Row],[Date of Call]],"dddd") -> Monday | L30: =TEXT(Calls[[#This Row],[Date of Call]],"mmm") -> Jan
A31: call_1029 | B31: C018 | C31: 19 | D31: R004 | E31: 6-Jan-25 | F31: 96 | G31: 4.7 | H31: =ROUND(Calls[[#This Row],[Satisfactory Rating]],0) -> 5 | I31: {=_xlfn.IFS(Calls[[#This Row],[Duration (Min)]]<=30,"Under 30 mins",Calls[[#This Row],[Duration (Min)]]<=60,"Under 1h",Calls[[#This Row],[Duration (Min)]]<=120,"Under 2",TRUE,"More than 2h")} -> Under 30 mins | J31: =IF(MONTH(Calls[[#This Row],[Date of Call]])<=3,YEAR(Calls[[#This Row],[Date of Call]]),YEAR(Calls[[#This Row],[Date of Call]])+1) -> 2025 | K31: =TEXT(Calls[[#This Row],[Date of Call]],"dddd") -> Monday | L31: =TEXT(Calls[[#This Row],[Date of Call]],"mmm") -> Jan
A32: call_1030 | B32: C004 | C32: 72 | D32: R002 | E32: 7-Jan-25 | F32: 66 | G32: 3.4 | H32: =ROUND(Calls[[#This Row],[Satisfactory Rating]],0) -> 3 | I32: {=_xlfn.IFS(Calls[[#This Row],[Duration (Min)]]<=30,"Under 30 mins",Calls[[#This Row],[Duration (Min)]]<=60,"Under 1h",Calls[[#This Row],[Duration (Min)]]<=120,"Under 2",TRUE,"More than 2h")} -> Under 2 | J32: =IF(MONTH(Calls[[#This Row],[Date of Call]])<=3,YEAR(Calls[[#This Row],[Date of Call]]),YEAR(Calls[[#This Row],[Date of Call]])+1) -> 2025 | K32: =TEXT(Calls[[#This Row],[Date of Call]],"dddd") -> Tuesday | L32: =TEXT(Calls[[#This Row],[Date of Call]],"mmm") -> Jan
A33: call_1031 | B33: C007 | C33: 138 | D33: R001 | E33: 7-Jan-25 | F33: 70 | G33: 3.7 | H33: =ROUND(Calls[[#This Row],[Satisfactory Rating]],0) -> 4 | I33: {=_xlfn.IFS(Calls[[#This Row],[Duration (Min)]]<=30,"Under 30 mins",Calls[[#This Row],[Duration (Min)]]<=60,"Under 1h",Calls[[#This Row],[Duration (Min)]]<=120,"Under 2",TRUE,"More than 2h")} -> More than 2h | J33: =IF(MONTH(Calls[[#This Row],[Date of Call]])<=3,YEAR(Calls[[#This Row],[Date of Call]]),YEAR(Calls[[#This Row],[Date of Call]])+1) -> 2025 | K33: =TEXT(Calls[[#This Row],[Date of Call]],"dddd") -> Tuesday | L33: =TEXT(Calls[[#This Row],[Date of Call]],"mmm") -> Jan
... A1001: call_1999 | B1001: C012 | C1001: 112 | D1001: R001 | E1001: 19-Jul-25 | F1001: 81 | G1001: 1.5 | H1001: =ROUND(Calls[[#This Row],[Satisfactory Rating]],0) -> 2 | I1001: {=_xlfn.IFS(Calls[[#This Row],[Duration (Min)]]<=30,"Under 30 mins",Calls[[#This Row],[Duration (Min)]]<=60,"Under 1h",Calls[[#This Row],[Duration (Min)]]<=120,"Under 2",TRUE,"More than 2h")} -> Under 2 | J1001: =IF(MONTH(Calls[[#This Row],[Date of Call]])<=3,YEAR(Calls[[#This Row],[Date of Call]]),YEAR(Calls[[#This Row],[Date of Call]])+1) -> 2026 | K1001: =TEXT(Calls[[#This Row],[Date of Call]],"dddd") -> Saturday | L1001: =TEXT(Calls[[#This Row],[Date of Call]],"mmm") -> Jul

Sheet Pivots
A2: 1 | J2: 4
A3: Call Count | B3: 5*Calls | C3: Average Rating | D3: Total Duration | E3: Total Amount | J3: Row Labels | K3: Call Count | L3: Total Amount | N3: for graph: | P3: Selected cell | Q3: =V4 -> R005 | V3: Row Labels
A4: 1000 | B4: 143 | C4: 3.0309 | D4: 87436 | E4: 84607 | J4: R001 | K4: 148 | L4: 13162 | N4: Reps | O4: Call count | P4: Total Amt. | Q4: Chart count | R4: Chart Amt. | V4: R005
J5: R002 | K5: 171 | L5: 14586 | N5: R001 | O5: 148 | P5: 13162 | Q5: =IF(N5=$Q$3,O5,NA()) -> #N/A | R5: =IF(N5=$Q$3,P5,NA()) -> #N/A
J6: R003 | K6: 147 | L6: 12499 | N6: R002 | O6: 171 | P6: 14586 | Q6: =IF(N6=$Q$3,O6,NA()) -> #N/A | R6: =IF(N6=$Q$3,P6,NA()) -> #N/A
J7: R004 | K7: 140 | L7: 11736 | N7: R003 | O7: 147 | P7: 12499 | Q7: =IF(N7=$Q$3,O7,NA()) -> #N/A | R7: =IF(N7=$Q$3,P7,NA()) -> #N/A
J8: R005 | K8: 118 | L8: 9359 | N8: R004 | O8: 140 | P8: 11736 | Q8: =IF(N8=$Q$3,O8,NA()) -> #N/A | R8: =IF(N8=$Q$3,P8,NA()) -> #N/A
J9: R006 | K9: 141 | L9: 11766 | N9: R005 | O9: 118 | P9: 9359 | Q9: =IF(N9=$Q$3,O9,NA()) -> 118 | R9: =IF(N9=$Q$3,P9,NA()) -> 9359
A10: Call Count | B10: 5*Calls | C10: Average Rating | D10: Total Duration | E10: Total Amount | J10: R007 | K10: 135 | L10: 11499 | N10: R006 | O10: 141 | P10: 11766 | Q10: =IF(N10=$Q$3,O10,NA()) -> #N/A | R10: =IF(N10=$Q$3,P10,NA()) -> #N/A
A11: 118 | B11: 14 | C11: 3.0110169 | D11: 11072 | E11: 9359 | J11: Grand Total | K11: 1000 | L11: 84607 | N11: R007 | O11: 135 | P11: 11499 | Q11: =IF(N11=$Q$3,O11,NA()) -> #N/A | R11: =IF(N11=$Q$3,P11,NA()) -> #N/A
A14: 2 | E14: 3 | J14: 5 | O14: 6
A15: Row Labels | B15: Call Count | C15: Call Count2 | E15: Row Labels | F15: Call Count | J15: Call Count | K15: Column Labels | O15: Row Labels | P15: Call Count
A16: Jan | B16: 12 | C16: 12 | E16: Sunday | F16: 15 | J16: Row Labels | K16: Female | L16: Male | M16: Grand Total | O16: 1 | P16: 12
A17: Feb | B17: 20 | C17: 20 | E17: Monday | F17: 16 | J17: Chennai | K17: 182 | L17: 96 | M17: 278 | O17: 2 | P17: 30
A18: Mar | B18: 20 | C18: 20 | E18: Tuesday | F18: 19 | J18: Madurai | K18: 124 | L18: 48 | M18: 172 | O18: 3 | P18: 29
A19: Apr | B19: 13 | C19: 13 | E19: Wednesday | F19: 17 | J19: Salem | L19: 280 | M19: 280 | O19: 4 | P19: 33
A20: May | B20: 19 | C20: 19 | E20: Thursday | F20: 16 | J20: Trichy | K20: 210 | L20: 60 | M20: 270 | O20: 5 | P20: 14
A21: Jun | B21: 22 | C21: 22 | E21: Friday | F21: 19 | J21: Grand Total | K21: 516 | L21: 484 | M21: 1000 | O21: Grand Total | P21: 118
A22: Jul | B22: 12 | C22: 12 | E22: Saturday | F22: 16
A23: Grand Total | B23: 118 | C23: 118 | E23: Grand Total | F23: 118
A26: 7 | B26: 7
A27: Total Amount | B27: Column Labels | M27: 8 | P27: Labels | R27: Reps | S27: Name
A28: Row Labels | B28: R001 | C28: R002 | D28: R003 | E28: R004 | F28: R005 | G28: R006 | H28: R007 | I28: Grand Total | R28: R001 | S28: Jack
A29: Chennai | M29: %of calls | N29: =A11/A4 -> 0.118 | P29: ="% of Calls:"&TEXT(N29,"0%") -> % of Calls:12% | R29: R002 | S29: Joe
A30: C001 | B30: 339 | C30: 568 | D30: 767 | E30: 341 | F30: 237 | G30: 800 | H30: 331 | I30: 3383 | M30: calls | N30: =_xlfn.XLOOKUP(V4,N5:N11,O5:O11) -> 118 | P30: =IF(COUNTA(V4:V10)>1,"","Call Rank:"&N30) -> Call Rank:118 | R30: R003 | S30: Damon
A31: C002 | B31: 245 | C31: 1052 | D31: 463 | E31: 47 | F31: 162 | G31: 446 | H31: 702 | I31: 3117 | M31: amount | N31: =_xlfn.XLOOKUP(V4,N5:N11,P5:P11) -> 9359 | P31: =IF(COUNTA(V4:V10)>1,"","Amount Rank:"&N31) -> Amount Rank:9359 | R31: R004 | S31: Nic
A32: C008 | B32: 424 | C32: 895 | D32: 605 | E32: 281 | F32: 266 | G32: 186 | H32: 589 | I32: 3246 | R32: R005 | S32: Rayana
A33: C014 | B33: 550 | C33: 866 | D33: 557 | E33: 384 | F33: 570 | G33: 333 | H33: 514 | I33: 3774 | M33: Call Rank | N33: =_xlfn.RANK.AVG(N30,O5:O11) -> 7 | P33: Name | R33: R006 | S33: Klaus
A34: C019 | B34: 682 | C34: 1129 | D34: 905 | E34: 718 | F34: 387 | G34: 886 | H34: 723 | I34: 5430 | M34: Amount Rank | N34: =_xlfn.RANK.AVG(N31,P5:P11) -> 7 | P34: =IF(COUNTA(V4:V10)>1,"",_xlfn.XLOOKUP(V4,R28:R34,S28:S34)) -> Rayana | R34: R007 | S34: Elena
A35: C020 | B35: 746 | C35: 802 | D35: 965 | E35: 731 | F35: 461 | G35: 351 | H35: 665 | I35: 4721
A36: Madurai
A37: C003 | B37: 437 | C37: 804 | D37: 749 | E37: 675 | F37: 675 | G37: 311 | H37: 39 | I37: 3690
A38: C011 | B38: 159 | C38: 569 | D38: 366 | E38: 583 | F38: 487 | G38: 508 | H38: 481 | I38: 3153
A39: C015 | B39: 346 | C39: 1001 | D39: 303 | E39: 660 | F39: 439 | G39: 961 | H39: 406 | I39: 4116
A40: C017 | B40: 539 | C40: 380 | D40: 502 | E40: 56 | F40: 316 | G40: 1139 | H40: 686 | I40: 3618
A41: Salem
A42: C005 | B42: 1022 | C42: 812 | D42: 696 | E42: 691 | F42: 883 | G42: 719 | H42: 193 | I42: 5016
A43: C009 | B43: 885 | C43: 527 | D43: 653 | E43: 670 | F43: 292 | G43: 418 | H43: 1041 | I43: 4486
A44: C010 | B44: 389 | C44: 922 | D44: 586 | E44: 581 | F44: 461 | G44: 346 | H44: 572 | I44: 3857
A45: C012 | B45: 1020 | C45: 630 | D45: 562 | E45: 434 | F45: 327 | G45: 724 | H45: 834 | I45: 4531
...

Sheet Customer Report
C2: CALL CENTRE REPORT-2025
R21: {=Pivots!B28:H28} -> R001 | S21: R002 | T21: R003 | U21: R004 | V21: R005 | W21: R006 | X21: R007 | Y21: TOTAL
Q22: {=IF(Pivots!A29:I52="","",Pivots!A29:I52)} -> Chennai
Q23: C001 | R23: 339 | S23: 568 | T23: 767 | U23: 341 | V23: 237 | W23: 800 | X23: 331 | Y23: 3383
Q24: C002 | R24: 245 | S24: 1052 | T24: 463 | U24: 47 | V24: 162 | W24: 446 | X24: 702 | Y24: 3117
Q25: C008 | R25: 424 | S25: 895 | T25: 605 | U25: 281 | V25: 266 | W25: 186 | X25: 589 | Y25: 3246
Q26: C014 | R26: 550 | S26: 866 | T26: 557 | U26: 384 | V26: 570 | W26: 333 | X26: 514 | Y26: 3774
Q27: C019 | R27: 682 | S27: 1129 | T27: 905 | U27: 718 | V27: 387 | W27: 886 | X27: 723 | Y27: 5430
Q28: C020 | R28: 746 | S28: 802 | T28: 965 | U28: 731 | V28: 461 | W28: 351 | X28: 665 | Y28: 4721
Q29: Madurai
Q30: C003 | R30: 437 | S30: 804 | T30: 749 | U30: 675 | V30: 675 | W30: 311 | X30: 39 | Y30: 3690
Q31: C011 | R31: 159 | S31: 569 | T31: 366 | U31: 583 | V31: 487 | W31: 508 | X31: 481 | Y31: 3153
Q32: C015 | R32: 346 | S32: 1001 | T32: 303 | U32: 660 | V32: 439 | W32: 961 | X32: 406 | Y32: 4116
Q33: C017 | R33: 539 | S33: 380 | T33: 502 | U33: 56 | V33: 316 | W33: 1139 | X33: 686 | Y33: 3618
Q34: Salem
Q35: C005 | R35: 1022 | S35: 812 | T35: 696 | U35: 691 | V35: 883 | W35: 719 | X35: 193 | Y35: 5016
N36: =Pivots!P34 -> Rayana | Q36: C009 | R36: 885 | S36: 527 | T36: 653 | U36: 670 | V36: 292 | W36: 418 | X36: 1041 | Y36: 4486
N37: =Pivots!P29 -> % of Calls:12% | Q37: C010 | R37: 389 | S37: 922 | T37: 586 | U37: 581 | V37: 461 | W37: 346 | X37: 572 | Y37: 3857
N38: =Pivots!P30 -> Call Rank:118 | Q38: C012 | R38: 1020 | S38: 630 | T38: 562 | U38: 434 | V38: 327 | W38: 724 | X38: 834 | Y38: 4531
N39: =Pivots!P31 -> Amount Rank:9359 | Q39: C018 | R39: 458 | S39: 504 | T39: 914 | U39: 1564 | V39: 1068 | W39: 670 | X39: 466 | Y39: 5644
Q40: Trichy
Q41: C004 | R41: 1046 | S41: 744 | T41: 742 | U41: 484 | V41: 311 | W41: 531 | X41: 664 | Y41: 4522
Q42: C006 | R42: 1141 | S42: 915 | T42: 596 | U42: 414 | V42: 579 | W42: 644 | X42: 919 | Y42: 5208
Q43: C007 | R43: 981 | S43: 322 | T43: 508 | U43: 759 | V43: 646 | W43: 674 | X43: 358 | Y43: 4248
Q44: C013 | R44: 929 | S44: 586 | T44: 758 | U44: 1108 | V44: 269 | W44: 510 | X44: 522 | Y44: 4682
Q45: C016 | R45: 824 | S45: 558 | T45: 302 | U45: 555 | V45: 523 | W45: 609 | X45: 794 | Y45: 4165
